<?xml version="1.0"?>
<robot name="black_description" xmlns:xacro="http://www.ros.org/wiki/xacro">

  <material name="black">
    <color rgba="0.0 0.0 0.0 1.0"/>
  </material>
  <material name="blue">
    <color rgba="0.0 0.0 0.8 1.0"/>
  </material>
  <material name="green">
    <color rgba="0.0 0.8 0.0 1.0"/>
  </material>
  <material name="grey">
    <color rgba="0.2 0.2 0.2 1.0"/>
  </material>
  <material name="silver">
    <color rgba="0.913725490196 0.913725490196 0.847058823529 1.0"/>
  </material>
  <material name="orange">
    <color rgba="0.12 0.15 0.2 1.0"/>
  </material>
  <material name="brown">
    <color rgba="0.870588235294 0.811764705882 0.764705882353 1.0"/>
  </material>
  <material name="red">
    <color rgba="0.8 0.0 0.0 1.0"/>
  </material>
  <material name="white">
    <color rgba="1.0 1.0 1.0 1.0"/>
  </material>

  <link name="base">
    <visual>
      <origin rpy="0 0 0" xyz="0 0 0"/>
      <geometry>
        <box size="0.001 0.001 0.001"/>
      </geometry>
    </visual>
  </link>

  <joint name="floating_base" type="fixed">
    <origin rpy="1.5708 0 0" xyz="0 0 0"/>
    <parent link="base"/>
    <child link="trunk"/>
  </joint>

  <link name="trunk">
    <inertial>
      <origin rpy="0 0 0" xyz="6.324E-05 -0.069364 -0.0057482"/>
      <mass value="5.4419"/>
      <inertia ixx="0.0071218" ixy="-1.7632E-07" ixz="-4.8929E-07" iyy="0.011488" iyz="-5.0758E-06" izz="0.0082732"/>
    </inertial>
    <visual>
      <origin rpy="0 0 0" xyz="0 0 0"/>
      <geometry>
        <mesh filename="../meshes/base_link.STL"/>
      </geometry>
      <material name="orange"/>
    </visual>
    <collision>
      <origin rpy="0 0 0" xyz="0 0 0"/>
      <geometry>
        <mesh filename="../meshes/base_link.STL"/>
      </geometry>
    </collision>
  </link>
  <joint name="imu_joint" type="fixed">
    <parent link="trunk"/>
    <child link="imu_link"/>
    <origin rpy="-1.5780 0 0" xyz="0 0 0"/>
  </joint>
  <link name="imu_link">
    <inertial>
      <mass value="0.001"/>
      <origin rpy="0 0 0" xyz="0 0 0"/>
      <inertia ixx="0.0001" ixy="0" ixz="0" iyy="0.0001" iyz="0" izz="0.0001"/>
    </inertial>
    <visual>
      <origin rpy="0 0 0" xyz="0 0 0"/>
      <geometry>
        <box size="0.001 0.001 0.001"/>
      </geometry>
      <material name="red"/>
    </visual>
  </link>
<!-- ===================== 左前腿（FL）===================== -->
<joint name="FL_hip_joint" type="revolute">
  <origin rpy="0 0 1.5708" xyz="0.060001 -0.06425 0.1566"/>
  <parent link="trunk"/>
  <child link="FL_hip"/>
  <axis xyz="0 0 1"/>
  <limit lower="-10" upper="10" effort="20" velocity="100"/>
</joint>
<link name="FL_hip">
  <inertial>
    <origin rpy="0 0 0" xyz="5.6642E-05 -0.014784 0.05138"/>
    <mass value="0.60559"/>
    <inertia ixx="0.00034154" ixy="6.9802E-08" ixz="1.0024E-06" iyy="0.00064932" iyz="8.7952E-06" izz="0.00037423"/>
  </inertial>
  <visual>
    <origin rpy="0 0 0" xyz="0 0 0"/>
    <geometry>
      <mesh filename="../meshes/LF_Link1.STL"/>
    </geometry>
    <material name="orange"/>
  </visual>
  <collision>
    <origin rpy="0 0 0" xyz="0 0 0"/>
    <geometry>
      <mesh filename="../meshes/LF_Link1.STL"/>
    </geometry>
  </collision>
</link>
<joint name="FL_thigh_joint" type="revolute">
  <origin rpy="1.5708 0 0" xyz="0 -0.0336 0.056"/>
  <parent link="FL_hip"/>
  <child link="FL_thigh"/>
  <axis xyz="0 0 1"/>
  <limit lower="-10" upper="10" effort="20" velocity="100"/>
</joint>
<link name="FL_thigh">
  <inertial>
    <origin rpy="0 0 0" xyz="0.00094558 -0.022839 0.038764"/>
    <mass value="0.80378"/>
    <inertia ixx="0.0011632" ixy="-7.5488E-05" ixz="-4.84E-08" iyy="0.00046561" iyz="8.6426E-08" izz="0.0015723"/>
  </inertial>
  <visual>
    <origin rpy="0 0 0" xyz="0 0 0"/>
    <geometry>
      <mesh filename="../meshes/LF_Link2.STL"/>
    </geometry>
    <material name="orange"/>
  </visual>
  <collision>
    <origin rpy="0 0 0" xyz="0 0 0"/>
    <geometry>
      <mesh filename="../meshes/LF_Link2.STL"/>
    </geometry>
  </collision>
</link>
<joint name="FL_calf_joint" type="revolute">
  <origin rpy="0 0 0" xyz="-0.0385 -0.24702 0.0602"/>
  <parent link="FL_thigh"/>
  <child link="FL_calf"/>
  <axis xyz="0 0 1"/>
  <limit lower="-10" upper="10" effort="20" velocity="100"/>
</joint>
<link name="FL_calf">
  <inertial>
    <origin rpy="0 0 0" xyz="-0.12367 0.070965 6.1707E-05"/>
    <mass value="0.27052"/>
    <inertia ixx="0.00028269" ixy="0.0004308" ixz="-3.4435E-08" iyy="0.0008032" iyz="-1.219E-10" izz="0.0010713"/>
  </inertial>
  <visual>
    <origin rpy="0 0 0" xyz="0 0 0"/>
    <geometry>
      <mesh filename="../meshes/LF_Link3.STL"/>
    </geometry>
    <material name="orange"/>
  </visual>
  <collision>
    <origin rpy="0 0 0" xyz="0 0 0"/>
    <geometry>
      <mesh filename="../meshes/LF_Link3.STL"/>
    </geometry>
  </collision>
</link>

<joint name="FL_foot_fixed" type="fixed" dont_collapse="true">
  <origin rpy="0 0 0" xyz="-0.24 0.105 0"/>
  <parent link="FL_calf"/>
  <child link="FL_foot"/>
</joint>
<link name="FL_foot">
  <visual>
    <origin rpy="0 0 0" xyz="0 0 0"/>
    <geometry>
      <sphere radius="0.02"/>
    </geometry>
    <material name="orange"/>
  </visual>
  <collision>
    <!-- <origin rpy="0 0 0" xyz="-0.24 0.105 0"/> -->
    <origin rpy="0 0 0" xyz="0 0 0"/>
    <geometry>
      <sphere radius="0.03"/>
    </geometry>
  </collision>
  <inertial>
    <mass value="0.1"/>
    <inertia ixx="1.6e-05" ixy="0" ixz="0" iyy="1.6e-05" iyz="0" izz="1.6e-05"/>
  </inertial>
</link>
<!-- ===================== 左前腿（FR）===================== -->
<joint name="FR_hip_joint" type="revolute">
  <origin rpy="0 0 1.5708" xyz="-0.059999 -0.06425 0.1566"/>
  <parent link="trunk"/>
  <child link="FR_hip"/>
  <axis xyz="0 0 1"/>
  <limit lower="-10" upper="10" effort="20" velocity="100"/>
</joint>

<link name="FR_hip">
  <inertial>
    <origin rpy="0 0 0" xyz="-5.6642E-05 0.014784 0.05138"/>
    <mass value="0.60559"/>
    <inertia ixx="0.00034154" ixy="6.9802E-08" ixz="-1.0024E-06" iyy="0.00064932" iyz="-8.7952E-06" izz="0.00037423"/>
  </inertial>
  <visual>
    <origin rpy="0 0 0" xyz="0 0 0"/>
    <geometry>
      <mesh filename="../meshes/RF_Link1.STL"/>
    </geometry>
    <material name="orange"/>
  </visual>
  <collision>
    <origin rpy="0 0 0" xyz="0 0 0"/>
    <geometry>
      <mesh filename="../meshes/RF_Link1.STL"/>
    </geometry>
  </collision>
</link>

<joint name="FR_thigh_joint" type="revolute">
  <origin rpy="-1.5708 0 0" xyz="0 0.0336 0.056"/>
  <parent link="FR_hip"/>
  <child link="FR_thigh"/>
  <axis xyz="0 0 1"/>
  <limit lower="-10" upper="10" effort="20" velocity="100"/>
</joint>

<link name="FR_thigh">
  <inertial>
    <origin rpy="0 0 0" xyz="0.0012123 0.02266 0.038629"/>
    <mass value="0.80378"/>
    <inertia ixx="0.0011641" ixy="7.8106E-05" ixz="-8.0916E-08" iyy="0.00046477" iyz="1.1193E-09" izz="0.0015723"/>
  </inertial>
  <visual>
    <origin rpy="0 0 0" xyz="0 0 0"/>
    <geometry>
      <mesh filename="../meshes/RF_Link2.STL"/>
    </geometry>
    <material name="orange"/>
  </visual>
  <collision>
    <origin rpy="0 0 0" xyz="0 0 0"/>
    <geometry>
      <mesh filename="../meshes/RF_Link2.STL"/>
    </geometry>
  </collision>
</link>

<joint name="FR_calf_joint" type="revolute">
  <origin rpy="0 0 0" xyz="-0.0385 0.24702 0.0599"/>
  <parent link="FR_thigh"/>
  <child link="FR_calf"/>
  <axis xyz="0 0 1"/>
  <limit lower="-10" upper="10" effort="20" velocity="100"/>
</joint>

<link name="FR_calf">
  <inertial>
    <origin rpy="0 0 0" xyz="-0.12367 -0.070965 -6.1707E-05"/>
    <mass value="0.27052"/>
    <inertia ixx="0.00028269" ixy="-0.0004308" ixz="3.4435E-08" iyy="0.0008032" iyz="-1.2189E-10" izz="0.0010713"/>
  </inertial>
  <visual>
    <origin rpy="0 0 0" xyz="0 0 0"/>
    <geometry>
      <mesh filename="../meshes/RF_Link3.STL"/>
    </geometry>
    <material name="orange"/>
  </visual>
  <collision>
    <origin rpy="0 0 0" xyz="0 0 0"/>
    <geometry>
      <mesh filename="../meshes/RF_Link3.STL"/>
    </geometry>
  </collision>
</link>

<joint name="FR_foot_fixed" type="fixed" dont_collapse="true">
  <origin rpy="0 0 0" xyz="-0.24 -0.105 0.0"/>
  <parent link="FR_calf"/>
  <child link="FR_foot"/>
</joint>

<link name="FR_foot">
  <visual>
    <!-- <origin rpy="0 0 0" xyz="-0.24 -0.105 0.2"/> -->
    <origin rpy="0 0 0" xyz="0 0 0"/>
    <geometry>
      <sphere radius="0.02"/>
    </geometry>
    <material name="orange"/>
  </visual>
  <collision>
    <!-- <origin rpy="0 0 0" xyz="-0.24 -0.105 0.2"/> -->
    <origin rpy="0 0 0" xyz="0 0 0"/>
    <geometry>
      <sphere radius="0.03"/>
    </geometry>
  </collision>
  <inertial>
    <mass value="0.1"/>
    <inertia ixx="1.6e-05" ixy="0" ixz="0" iyy="1.6e-05" iyz="0" izz="1.6e-05"/>
  </inertial>
</link>

<!-- ===================== 右后腿（RR）===================== -->
<joint name="RR_hip_joint" type="revolute">
  <origin rpy="-3.1416 0 1.5708" xyz="-0.059999 -0.06425 -0.1566"/>
  <parent link="trunk"/>
  <child link="RR_hip"/>
  <axis xyz="0 0 1"/>
  <limit lower="-10" upper="10" effort="20" velocity="100"/>
</joint>

<link name="RR_hip">
  <inertial>
    <origin rpy="0 0 0" xyz="5.6642E-05 -0.014784 0.05138"/>
    <mass value="0.60559"/>
    <inertia ixx="0.00034154" ixy="6.9802E-08" ixz="1.0024E-06" iyy="0.00064932" iyz="8.7952E-06" izz="0.00037423"/>
  </inertial>
  <visual>
    <origin rpy="0 0 0" xyz="0 0 0"/>
    <geometry>
      <mesh filename="../meshes/RR_Link1.STL"/>
    </geometry>
    <material name="orange"/>
  </visual>
  <collision>
    <origin rpy="0 0 0" xyz="0 0 0"/>
    <geometry>
      <mesh filename="../meshes/RR_Link1.STL"/>
    </geometry>
  </collision>
</link>

<joint name="RR_thigh_joint" type="revolute">
  <origin rpy="1.5708 0 0" xyz="0 -0.0336 0.056"/>
  <parent link="RR_hip"/>
  <child link="RR_thigh"/>
  <axis xyz="0 0 1"/>
  <limit lower="-10" upper="10" effort="20" velocity="100"/>
</joint>

<link name="RR_thigh">
  <inertial>
    <origin rpy="0 0 0" xyz="0.0012123 0.02266 0.038629"/>
    <mass value="0.80378"/>
    <inertia ixx="0.0011641" ixy="7.8106E-05" ixz="-8.0915E-08" iyy="0.00046477" iyz="1.1195E-09" izz="0.0015723"/>
  </inertial>
  <visual>
    <origin rpy="0 0 0" xyz="0 0 0"/>
    <geometry>
      <mesh filename="../meshes/RR_Link2.STL"/>
    </geometry>
    <material name="orange"/>
  </visual>
  <collision>
    <origin rpy="0 0 0" xyz="0 0 0"/>
    <geometry>
      <mesh filename="../meshes/RR_Link2.STL"/>
    </geometry>
  </collision>
</link>

<joint name="RR_calf_joint" type="revolute">
  <origin rpy="0 0 0" xyz="-0.0385 0.24702 0.0599"/>
  <parent link="RR_thigh"/>
  <child link="RR_calf"/>
  <axis xyz="0 0 1"/>
  <limit lower="-10" upper="10" effort="20" velocity="100"/>
</joint>

<link name="RR_calf">
  <inertial>
    <origin rpy="0 0 0" xyz="-0.12367 -0.070965 -6.1706E-05"/>
    <mass value="0.27052"/>
    <inertia ixx="0.00028269" ixy="-0.0004308" ixz="3.4436E-08" iyy="0.0008032" iyz="-1.2131E-10" izz="0.0010713"/>
  </inertial>
  <visual>
    <origin rpy="0 0 0" xyz="0 0 0"/>
    <geometry>
      <mesh filename="../meshes/RR_Link3.STL"/>
    </geometry>
    <material name="orange"/>
  </visual>
  <collision>
    <origin rpy="0 0 0" xyz="0 0 0"/>
    <geometry>
      <mesh filename="../meshes/RR_Link3.STL"/>
    </geometry>
  </collision>
</link>


<joint name="RR_foot_fixed" type="fixed" dont_collapse="true">
  <origin rpy="0 0 0" xyz="-0.24 -0.105 0.0"/>
  <parent link="RR_calf"/>
  <child link="RR_foot"/>
</joint>

<link name="RR_foot">
  <visual>
    <origin rpy="0 0 0" xyz="0 0 0"/>
    <geometry>
      <sphere radius="0.02"/>
    </geometry>
    <material name="orange"/>
  </visual>
  <collision>
    <!-- <origin rpy="0 0 0" xyz="-0.24 -0.105 0.20"/> -->
    <origin rpy="0 0 0" xyz="0 0 0"/>
    <geometry>
      <sphere radius="0.03"/>
    </geometry>
  </collision>
  <inertial>
    <mass value="0.1"/>
    <inertia ixx="1.6e-05" ixy="0" ixz="0" iyy="1.6e-05" iyz="0" izz="1.6e-05"/>
  </inertial>
</link>

  <!-- ===================== 左后腿（RL）===================== -->
<joint name="RL_hip_joint" type="revolute">
  <origin rpy="-3.1416 0 1.5708" xyz="0.060001 -0.06425 -0.1566"/>
  <parent link="trunk"/>
  <child link="RL_hip"/>
  <axis xyz="0 0 1"/>
  <limit lower="-10" upper="10" effort="20" velocity="100"/>
</joint>

<link name="RL_hip">
  <inertial>
    <origin rpy="0 0 0" xyz="-5.6642E-05 0.014784 0.05138"/>
    <mass value="0.60559"/>
    <inertia ixx="0.00034154" ixy="6.9802E-08" ixz="-1.0024E-06" iyy="0.00064932" iyz="-8.7952E-06" izz="0.00037423"/>
  </inertial>
  <visual>
    <origin rpy="0 0 0" xyz="0 0 0"/>
    <geometry>
      <mesh filename="../meshes/LR_Link1.STL"/>
    </geometry>
    <material name="orange"/>
  </visual>
  <collision>
    <origin rpy="0 0 0" xyz="0 0 0"/>
    <geometry>
      <mesh filename="../meshes/LR_Link1.STL"/>
    </geometry>
  </collision>
</link>

<joint name="RL_thigh_joint" type="revolute">
  <origin rpy="-1.5708 0 0" xyz="0 0.0336 0.056"/>
  <parent link="RL_hip"/>
  <child link="RL_thigh"/>
  <axis xyz="0 0 1"/>
  <limit lower="-10" upper="10" effort="20" velocity="100"/>
</joint>

<link name="RL_thigh">
  <inertial>
    <origin rpy="0 0 0" xyz="0.00094558 -0.022839 0.038764"/>
    <mass value="0.80378"/>
    <inertia ixx="0.0011632" ixy="-7.5488E-05" ixz="-4.84E-08" iyy="0.00046561" iyz="8.6426E-08" izz="0.0015723"/>
  </inertial>
  <visual>
    <origin rpy="0 0 0" xyz="0 0 0"/>
    <geometry>
      <mesh filename="../meshes/LR_Link2.STL"/>
    </geometry>
    <material name="orange"/>
  </visual>
  <collision>
    <origin rpy="0 0 0" xyz="0 0 0"/>
    <geometry>
      <mesh filename="../meshes/LR_Link2.STL"/>
    </geometry>
  </collision>
</link>

<joint name="RL_calf_joint" type="revolute">
  <origin rpy="0 0 0" xyz="-0.0385 -0.24702 0.0602"/>
  <parent link="RL_thigh"/>
  <child link="RL_calf"/>
  <axis xyz="0 0 -1"/>
  <limit lower="-10" upper="10" effort="20" velocity="100"/>
</joint>

<link name="RL_calf">
  <inertial>
    <origin rpy="0 0 0" xyz="-0.12367 0.070965 6.1705E-05"/>
    <mass value="0.27052"/>
    <inertia ixx="0.00028269" ixy="0.0004308" ixz="-3.4435E-08" iyy="0.0008032" iyz="-1.217E-10" izz="0.0010713"/>
  </inertial>
  <visual>
    <origin rpy="0 0 0" xyz="0 0 0"/>
    <geometry>
      <mesh filename="../meshes/LR_Link3.STL"/>
    </geometry>
    <material name="orange"/>
  </visual>
  <collision>
    <origin rpy="0 0 0" xyz="0 0 0"/>
    <geometry>
      <mesh filename="../meshes/LR_Link3.STL"/>
    </geometry>
  </collision>
</link>

<joint name="RL_foot_fixed" type="fixed" dont_collapse="true">
  <!-- <origin rpy="0 0 0" xyz="0 0 -0.2"/> -->
  <origin rpy="0 0 0" xyz="-0.24 0.105 0"/>
  <parent link="RL_calf"/>
  <child link="RL_foot"/>
</joint>

<link name="RL_foot">
  <visual>
    <!-- <origin rpy="0 0 0" xyz="-0.24 0.105 0.20"/> -->
    <origin rpy="0 0 0" xyz="0 0 0"/>
    <geometry>
      <sphere radius="0.02"/>
    </geometry>
    <material name="orange"/>
  </visual>
  <collision>
    <!-- <origin rpy="0 0 0" xyz="-0.24 0.105 0.20"/> -->
    <origin rpy="0 0 0" xyz="0 0 0"/>
    <geometry>
      <sphere radius="0.03"/>
    </geometry>
  </collision>
  <inertial>
    <mass value="0.1"/>
    <inertia ixx="1.6e-05" ixy="0" ixz="0" iyy="1.6e-05" iyz="0" izz="1.6e-05"/>
  </inertial>
</link>

</robot>