<?xml version="1.0" ?>
<robot xmlns:xacro="http://www.ros.org/wiki/xacro" name="black">
  <material name="black">
    <color rgba="0.0 0.0 0.0 1.0"/>
  </material>
  <material name="blue">
    <color rgba="0.0 0.0 0.8 1.0"/>
  </material>
  <material name="green">
    <color rgba="0.0 0.8 0.0 1.0"/>
  </material>
  <material name="grey">
    <color rgba="0.2 0.2 0.2 1.0"/>
  </material>
  <material name="silver">
    <color rgba="0.913725490196 0.913725490196 0.847058823529 1.0"/>
  </material>
  <material name="orange">
    <!-- <color rgba="1.0 0.423529411765 0.0392156862745 1.0"/> -->
    <color rgba="0.12 0.15 0.2 1.0"/>
  </material>
  <material name="brown">
    <color rgba="0.870588235294 0.811764705882 0.764705882353 1.0"/>
  </material>
  <material name="red">
    <color rgba="0.8 0.0 0.0 1.0"/>
  </material>
  <material name="white">
    <color rgba="1.0 1.0 1.0 1.0"/>
  </material>






















  
  <link
    name="base_link">
    <inertial>
      <origin
        xyz="6.324E-05 -0.069364 -0.0057482"
        rpy="0 0 0" />
      <mass
        value="5.4419" />
      <inertia
        ixx="0.0071218"
        ixy="-1.7632E-07"
        ixz="-4.8929E-07"
        iyy="0.011488"
        iyz="-5.0758E-06"
        izz="0.0082732" />
    </inertial>
    <visual>
      <origin
        xyz="0 0 0"
        rpy="0 0 0" />
      <geometry>
        <mesh
          filename="package://go_urdf/meshes/base_link.STL" />
      </geometry>
      <material
        name="">
        <color
          rgba="1 1 1 1" />
      </material>
    </visual>
    <collision>
      <origin
        xyz="0 0 0"
        rpy="0 0 0" />
      <geometry>
        <mesh
          filename="package://go_urdf/meshes/base_link.STL" />
      </geometry>
    </collision>
  </link>
  <link
    name="LF_Link1">
    <inertial>
      <origin
        xyz="5.6642E-05 -0.014784 0.05138"
        rpy="0 0 0" />
      <mass
        value="0.60559" />
      <inertia
        ixx="0.00034154"
        ixy="6.9802E-08"
        ixz="1.0024E-06"
        iyy="0.00064932"
        iyz="8.7952E-06"
        izz="0.00037423" />
    </inertial>
    <visual>
      <origin
        xyz="0 0 0"
        rpy="0 0 0" />
      <geometry>
        <mesh
          filename="package://go_urdf/meshes/LF_Link1.STL" />
      </geometry>
      <material
        name="">
        <color
          rgba="1 0.5 0.5 1" />
      </material>
    </visual>
    <collision>
      <origin
        xyz="0 0 0"
        rpy="0 0 0" />
      <geometry>
        <mesh
          filename="package://go_urdf/meshes/LF_Link1.STL" />
      </geometry>
    </collision>
  </link>
  <joint
    name="LF1"
    type="revolute">
    <origin
      xyz="0.060001 -0.06425 0.1566"
      rpy="0 0 1.5708" />
    <parent
      link="base_link" />
    <child
      link="LF_Link1" />
    <axis
      xyz="0 0 1" />
    <!-- <limit
      lower="-1.047"
      upper="1.047"
      effort="0"
      velocity="0" /> -->
  </joint>
  <link
    name="LF_Link2">
    <inertial>
      <origin
        xyz="0.00094558 -0.022839 0.038764"
        rpy="0 0 0" />
      <mass
        value="0.80378" />
      <inertia
        ixx="0.0011632"
        ixy="-7.5488E-05"
        ixz="-4.84E-08"
        iyy="0.00046561"
        iyz="8.6426E-08"
        izz="0.0015723" />
    </inertial>
    <visual>
      <origin
        xyz="0 0 0"
        rpy="0 0 0" />
      <geometry>
        <mesh
          filename="package://go_urdf/meshes/LF_Link2.STL" />
      </geometry>
      <material
        name="">
        <color
          rgba="0.3 0.3 1 1" />
      </material>
    </visual>
    <collision>
      <origin
        xyz="0 0 0"
        rpy="0 0 0" />
      <geometry>
        <mesh
          filename="package://go_urdf/meshes/LF_Link2.STL" />
      </geometry>
    </collision>
  </link>
  <joint
    name="LF2"
    type="continuous">
    <origin
      xyz="0 -0.0336 0.056"
      rpy="1.5708 0 0" />
    <parent
      link="LF_Link1" />
    <child
      link="LF_Link2" />
    <axis
      xyz="0 0 1" />
    <!-- <limit
      lower="0"
      upper="0"
      effort="0"
      velocity="0" /> -->
  </joint>
  <link
    name="LF_Link3">
    <inertial>
      <origin
        xyz="-0.12367 0.070965 6.1707E-05"
        rpy="0 0 0" />
      <mass
        value="0.27052" />
      <inertia
        ixx="0.00028269"
        ixy="0.0004308"
        ixz="-3.4435E-08"
        iyy="0.0008032"
        iyz="-1.219E-10"
        izz="0.0010713" />
    </inertial>
    <visual>
      <origin
        xyz="0 0 0"
        rpy="0 0 0" />
      <geometry>
        <mesh
          filename="package://go_urdf/meshes/LF_Link3.STL" />
      </geometry>
      <material
        name="">
        <color
          rgba="0.5 1 0.5 1" />
      </material>
    </visual>
    <collision>
      <origin
        xyz="0 0 0"
        rpy="0 0 0" />
      <geometry>
        <mesh
          filename="package://go_urdf/meshes/LF_Link3.STL" />
      </geometry>
    </collision>
  </link>
  <joint
    name="LF3"
    type="revolute">
    <origin
      xyz="-0.0385 -0.24702 0.0602"
      rpy="0 0 0" />
    <parent
      link="LF_Link2" />
    <child
      link="LF_Link3" />
    <axis
      xyz="0 0 1" />
    <!-- <limit
      lower="-0.523"
      upper="0.523"
      effort="0"
      velocity="0" /> -->
  </joint>
  <link
    name="RF_Link1">
    <inertial>
      <origin
        xyz="-5.6642E-05 0.014784 0.05138"
        rpy="0 0 0" />
      <mass
        value="0.60559" />
      <inertia
        ixx="0.00034154"
        ixy="6.9802E-08"
        ixz="-1.0024E-06"
        iyy="0.00064932"
        iyz="-8.7952E-06"
        izz="0.00037423" />
    </inertial>
    <visual>
      <origin
        xyz="0 0 0"
        rpy="0 0 0" />
      <geometry>
        <mesh
          filename="package://go_urdf/meshes/RF_Link1.STL" />
      </geometry>
      <material
        name="">
        <color
          rgba="1 0.5 0.5 1" />
      </material>
    </visual>
    <collision>
      <origin
        xyz="0 0 0"
        rpy="0 0 0" />
      <geometry>
        <mesh
          filename="package://go_urdf/meshes/RF_Link1.STL" />
      </geometry>
    </collision>
  </link>
  <joint
    name="RF1"
    type="revolute">
    <origin
      xyz="-0.059999 -0.06425 0.1566"
      rpy="0 0 1.5708" />
    <parent
      link="base_link" />
    <child
      link="RF_Link1" />
    <axis
      xyz="0 0 1" />
    <!-- <limit
      lower="-1.047"
      upper="1.047"
      effort="0"
      velocity="0" /> -->
  </joint>
  <link
    name="RF_Link2">
    <inertial>
      <origin
        xyz="0.0012123 0.02266 0.038629"
        rpy="0 0 0" />
      <mass
        value="0.80378" />
      <inertia
        ixx="0.0011641"
        ixy="7.8106E-05"
        ixz="-8.0916E-08"
        iyy="0.00046477"
        iyz="1.1193E-09"
        izz="0.0015723" />
    </inertial>
    <visual>
      <origin
        xyz="0 0 0"
        rpy="0 0 0" />
      <geometry>
        <mesh
          filename="package://go_urdf/meshes/RF_Link2.STL" />
      </geometry>
      <material
        name="">
        <color
          rgba="0.3 0.3 1 1" />
      </material>
    </visual>
    <collision>
      <origin
        xyz="0 0 0"
        rpy="0 0 0" />
      <geometry>
        <mesh
          filename="package://go_urdf/meshes/RF_Link2.STL" />
      </geometry>
    </collision>
  </link>
  <joint
    name="RF2"
    type="continuous">
    <origin
      xyz="0 0.0336 0.056"
      rpy="-1.5708 0 0" />
    <parent
      link="RF_Link1" />
    <child
      link="RF_Link2" />
    <axis
      xyz="0 0 1" />
    <!-- <limit
      lower="0"
      upper="0"
      effort="0"
      velocity="0" /> -->
  </joint>
  <link
    name="RF_Link3">
    <inertial>
      <origin
        xyz="-0.12367 -0.070965 -6.1707E-05"
        rpy="0 0 0" />
      <mass
        value="0.27052" />
      <inertia
        ixx="0.00028269"
        ixy="-0.0004308"
        ixz="3.4435E-08"
        iyy="0.0008032"
        iyz="-1.2189E-10"
        izz="0.0010713" />
    </inertial>
    <visual>
      <origin
        xyz="0 0 0"
        rpy="0 0 0" />
      <geometry>
        <mesh
          filename="package://go_urdf/meshes/RF_Link3.STL" />
      </geometry>
      <material
        name="">
        <color
          rgba="0.5 1 0.5 1" />
      </material>
    </visual>
    <collision>
      <origin
        xyz="0 0 0"
        rpy="0 0 0" />
      <geometry>
        <mesh
          filename="package://go_urdf/meshes/RF_Link3.STL" />
      </geometry>
    </collision>
  </link>
  <joint
    name="RF3"
    type="revolute">
    <origin
      xyz="-0.0385 0.24702 0.0599"
      rpy="0 0 0" />
    <parent
      link="RF_Link2" />
    <child
      link="RF_Link3" />
    <axis
      xyz="0 0 1" />
    <!-- <limit
      lower="-0.523"
      upper="0.523"
      effort="0"
      velocity="0" /> -->
  </joint>
  <link
    name="LR_Link1">
    <inertial>
      <origin
        xyz="-5.6642E-05 0.014784 0.05138"
        rpy="0 0 0" />
      <mass
        value="0.60559" />
      <inertia
        ixx="0.00034154"
        ixy="6.9802E-08"
        ixz="-1.0024E-06"
        iyy="0.00064932"
        iyz="-8.7952E-06"
        izz="0.00037423" />
    </inertial>
    <visual>
      <origin
        xyz="0 0 0"
        rpy="0 0 0" />
      <geometry>
        <mesh
          filename="package://go_urdf/meshes/LR_Link1.STL" />
      </geometry>
      <material
        name="">
        <color
          rgba="1 0.5 0.5 1" />
      </material>
    </visual>
    <collision>
      <origin
        xyz="0 0 0"
        rpy="0 0 0" />
      <geometry>
        <mesh
          filename="package://go_urdf/meshes/LR_Link1.STL" />
      </geometry>
    </collision>
  </link>
  <joint
    name="LR1"
    type="revolute">
    <origin
      xyz="0.060001 -0.06425 -0.1566"
      rpy="-3.1416 0 1.5708" />
    <parent
      link="base_link" />
    <child
      link="LR_Link1" />
    <axis
      xyz="0 0 1" />
    <!-- <limit
      lower="-1.047"
      upper="1.047"
      effort="0"
      velocity="0" /> -->
  </joint>
  <link
    name="LR_Link2">
    <inertial>
      <origin
        xyz="0.00094558 -0.022839 0.038764"
        rpy="0 0 0" />
      <mass
        value="0.80378" />
      <inertia
        ixx="0.0011632"
        ixy="-7.5488E-05"
        ixz="-4.84E-08"
        iyy="0.00046561"
        iyz="8.6426E-08"
        izz="0.0015723" />
    </inertial>
    <visual>
      <origin
        xyz="0 0 0"
        rpy="0 0 0" />
      <geometry>
        <mesh
          filename="package://go_urdf/meshes/LR_Link2.STL" />
      </geometry>
      <material
        name="">
        <color
          rgba="0.3 0.3 1 1" />
      </material>
    </visual>
    <collision>
      <origin
        xyz="0 0 0"
        rpy="0 0 0" />
      <geometry>
        <mesh
          filename="package://go_urdf/meshes/LR_Link2.STL" />
      </geometry>
    </collision>
  </link>
  <joint
    name="LR2"
    type="continuous">
    <origin
      xyz="0 0.0336 0.056"
      rpy="-1.5708 0 0" />
    <parent
      link="LR_Link1" />
    <child
      link="LR_Link2" />
    <axis
      xyz="0 0 1" />
    <!-- <limit
      lower="0"
      upper="0"
      effort="0"
      velocity="0" /> -->
  </joint>
  <link
    name="LR_Link3">
    <inertial>
      <origin
        xyz="-0.12367 0.070965 6.1705E-05"
        rpy="0 0 0" />
      <mass
        value="0.27052" />
      <inertia
        ixx="0.00028269"
        ixy="0.0004308"
        ixz="-3.4435E-08"
        iyy="0.0008032"
        iyz="-1.217E-10"
        izz="0.0010713" />
    </inertial>
    <visual>
      <origin
        xyz="0 0 0"
        rpy="0 0 0" />
      <geometry>
        <mesh
          filename="package://go_urdf/meshes/LR_Link3.STL" />
      </geometry>
      <material
        name="">
        <color
          rgba="0.5 1 0.5 1" />
      </material>
    </visual>
    <collision>
      <origin
        xyz="0 0 0"
        rpy="0 0 0" />
      <geometry>
        <mesh
          filename="package://go_urdf/meshes/LR_Link3.STL" />
      </geometry>
    </collision>
  </link>
  <joint
    name="LR3"
    type="revolute">
    <origin
      xyz="-0.0385 -0.24702 0.0602"
      rpy="0 0 0" />
    <parent
      link="LR_Link2" />
    <child
      link="LR_Link3" />
    <axis
      xyz="0 0 -1" />
    <!-- <limit
      lower="-0.523"
      upper="0.523"
      effort="0"
      velocity="0" /> -->
  </joint>
  <link
    name="RR_Link1">
    <inertial>
      <origin
        xyz="5.6642E-05 -0.014784 0.05138"
        rpy="0 0 0" />
      <mass
        value="0.60559" />
      <inertia
        ixx="0.00034154"
        ixy="6.9802E-08"
        ixz="1.0024E-06"
        iyy="0.00064932"
        iyz="8.7952E-06"
        izz="0.00037423" />
    </inertial>
    <visual>
      <origin
        xyz="0 0 0"
        rpy="0 0 0" />
      <geometry>
        <mesh
          filename="package://go_urdf/meshes/RR_Link1.STL" />
      </geometry>
      <material
        name="">
        <color
          rgba="1 0.5 0.5 1" />
      </material>
    </visual>
    <collision>
      <origin
        xyz="0 0 0"
        rpy="0 0 0" />
      <geometry>
        <mesh
          filename="package://go_urdf/meshes/RR_Link1.STL" />
      </geometry>
    </collision>
  </link>
  <joint
    name="RR1"
    type="revolute">
    <origin
      xyz="-0.059999 -0.06425 -0.1566"
      rpy="-3.1416 0 1.5708" />
    <parent
      link="base_link" />
    <child
      link="RR_Link1" />
    <axis
      xyz="0 0 1" />
    <!-- <limit
      lower="-1.047"
      upper="1.047"
      effort="0"
      velocity="0" /> -->
  </joint>
  <link
    name="RR_Link2">
    <inertial>
      <origin
        xyz="0.0012123 0.02266 0.038629"
        rpy="0 0 0" />
      <mass
        value="0.80378" />
      <inertia
        ixx="0.0011641"
        ixy="7.8106E-05"
        ixz="-8.0915E-08"
        iyy="0.00046477"
        iyz="1.1195E-09"
        izz="0.0015723" />
    </inertial>
    <visual>
      <origin
        xyz="0 0 0"
        rpy="0 0 0" />
      <geometry>
        <mesh
          filename="package://go_urdf/meshes/RR_Link2.STL" />
      </geometry>
      <material
        name="">
        <color
          rgba="0.3 0.3 1 1" />
      </material>
    </visual>
    <collision>
      <origin
        xyz="0 0 0"
        rpy="0 0 0" />
      <geometry>
        <mesh
          filename="package://go_urdf/meshes/RR_Link2.STL" />
      </geometry>
    </collision>
  </link>
  <joint
    name="RR2"
    type="continuous">
    <origin
      xyz="0 -0.0336 0.056"
      rpy="1.5708 0 0" />
    <parent
      link="RR_Link1" />
    <child
      link="RR_Link2" />
    <axis
      xyz="0 0 1" />
    <!-- <limit
      lower="0"
      upper="0"
      effort="0"
      velocity="0" /> -->
  </joint>
  <link
    name="RR_Link3">
    <inertial>
      <origin
        xyz="-0.12367 -0.070965 -6.1706E-05"
        rpy="0 0 0" />
      <mass
        value="0.27052" />
      <inertia
        ixx="0.00028269"
        ixy="-0.0004308"
        ixz="3.4436E-08"
        iyy="0.0008032"
        iyz="-1.2131E-10"
        izz="0.0010713" />
    </inertial>
    <visual>
      <origin
        xyz="0 0 0"
        rpy="0 0 0" />
      <geometry>
        <mesh
          filename="package://go_urdf/meshes/RR_Link3.STL" />
      </geometry>
      <material
        name="">
        <color
          rgba="0.5 1 0.5 1" />
      </material>
    </visual>
    <collision>
      <origin
        xyz="0 0 0"
        rpy="0 0 0" />
      <geometry>
        <mesh
          filename="package://go_urdf/meshes/RR_Link3.STL" />
      </geometry>
    </collision>
  </link>
  <joint
    name="RR3"
    type="revolute">
    <origin
      xyz="-0.0385 0.24702 0.0599"
      rpy="0 0 0" />
    <parent
      link="RR_Link2" />
    <child
      link="RR_Link3" />
    <axis
      xyz="0 0 1" />
    <!-- <limit
      lower="-0.523"
      upper="0.523"
      effort="0"
      velocity="0" /> -->
  </joint>
  
  <link name="base_footprint" />
  <joint name="base_joint" type="fixed">
    <parent link="base_footprint"/>
    <child link="base_link"/>
  </joint>


</robot>